Workbook

Sheet Главный
A1: Кол-во команд | B1: Подразделение | C1: Жребий | D1: Капитаны | E1: Тел.
A2: 1 | B2: =IFERROR(INDEX(Список!A:A,MATCH(D2,Список!B:B,0)),"") -> СМП | C2: 8 | D2: =IFERROR(INDEX(Список!B:B,MATCH(1,INDEX((COUNTIF(D1:D$1,Список!B:B)=0)/(Список!F:F="А"),0),0)),"") -> Развин Вячеслав Александрович | E2: =IFERROR(INDEX(Список!G:G,MATCH(D2,Список!B:B,0)),"") -> 11
A3: 2 | B3: =IFERROR(INDEX(Список!A:A,MATCH(D3,Список!B:B,0)),"") -> МП | C3: 7 | D3: =IFERROR(INDEX(Список!B:B,MATCH(1,INDEX((COUNTIF(D$1:D2,Список!B:B)=0)/(Список!F:F="А"),0),0)),"") -> Саматов Михаил Васильевич | E3: =IFERROR(INDEX(Список!G:G,MATCH(D3,Список!B:B,0)),"") -> 22
A4: 3 | B4: =IFERROR(INDEX(Список!A:A,MATCH(D4,Список!B:B,0)),"") -> ц.35 | C4: 14 | D4: =IFERROR(INDEX(Список!B:B,MATCH(1,INDEX((COUNTIF(D$1:D3,Список!B:B)=0)/(Список!F:F="А"),0),0)),"") -> Клевакина Лариса Геннадьевна | E4: =IFERROR(INDEX(Список!G:G,MATCH(D4,Список!B:B,0)),"") -> 33
A5: 4 | B5: =IFERROR(INDEX(Список!A:A,MATCH(D5,Список!B:B,0)),"") -> ц.38 | C5: 2 | D5: =IFERROR(INDEX(Список!B:B,MATCH(1,INDEX((COUNTIF(D$1:D4,Список!B:B)=0)/(Список!F:F="А"),0),0)),"") -> Снежкова Татьяна Александровна | E5: =IFERROR(INDEX(Список!G:G,MATCH(D5,Список!B:B,0)),"") -> 44
A6: 5 | B6: =IFERROR(INDEX(Список!A:A,MATCH(D6,Список!B:B,0)),"") -> СГМ | C6: 13 | D6: =IFERROR(INDEX(Список!B:B,MATCH(1,INDEX((COUNTIF(D$1:D5,Список!B:B)=0)/(Список!F:F="А"),0),0)),"") -> Грушецкий Вячеслав Валерьевич | E6: =IFERROR(INDEX(Список!G:G,MATCH(D6,Список!B:B,0)),"") -> 55
A7: 6 | B7: =IFERROR(INDEX(Список!A:A,MATCH(D7,Список!B:B,0)),"") -> ц.63 | C7: 12 | D7: =IFERROR(INDEX(Список!B:B,MATCH(1,INDEX((COUNTIF(D$1:D6,Список!B:B)=0)/(Список!F:F="А"),0),0)),"") -> Дахов Артур Сергеевич | E7: =IFERROR(INDEX(Список!G:G,MATCH(D7,Список!B:B,0)),"") -> 66
A8: 7 | B8: =IFERROR(INDEX(Список!A:A,MATCH(D8,Список!B:B,0)),"") -> ц.65 | C8: 3 | D8: =IFERROR(INDEX(Список!B:B,MATCH(1,INDEX((COUNTIF(D$1:D7,Список!B:B)=0)/(Список!F:F="А"),0),0)),"") -> Шахматов Вячеслав Владимирович | E8: =IFERROR(INDEX(Список!G:G,MATCH(D8,Список!B:B,0)),"") -> 78
A9: 8 | B9: =IFERROR(INDEX(Список!A:A,MATCH(D9,Список!B:B,0)),"") -> АХС | C9: 4 | D9: =IFERROR(INDEX(Список!B:B,MATCH(1,INDEX((COUNTIF(D$1:D8,Список!B:B)=0)/(Список!F:F="А"),0),0)),"") -> Книга Михаил Александрович | E9: =IFERROR(INDEX(Список!G:G,MATCH(D9,Список!B:B,0)),"") -> 87
A10: 9 | B10: =IFERROR(INDEX(Список!A:A,MATCH(D10,Список!B:B,0)),"") -> ОТД+ОГК | C10: 5 | D10: =IFERROR(INDEX(Список!B:B,MATCH(1,INDEX((COUNTIF(D$1:D9,Список!B:B)=0)/(Список!F:F="А"),0),0)),"") -> Павлюченко Елена Юрьевна | E10: =IFERROR(INDEX(Список!G:G,MATCH(D10,Список!B:B,0)),"") -> 741
A11: 10 | B11: =IFERROR(INDEX(Список!A:A,MATCH(D11,Список!B:B,0)),"") -> ОГТ | C11: 6 | D11: =IFERROR(INDEX(Список!B:B,MATCH(1,INDEX((COUNTIF(D$1:D10,Список!B:B)=0)/(Список!F:F="А"),0),0)),"") -> Грязнов Владимир Александрович | E11: =IFERROR(INDEX(Список!G:G,MATCH(D11,Список!B:B,0)),"") -> 111
A12: 11 | B12: =IFERROR(INDEX(Список!A:A,MATCH(D12,Список!B:B,0)),"") -> СУКП | C12: 11 | D12: =IFERROR(INDEX(Список!B:B,MATCH(1,INDEX((COUNTIF(D$1:D11,Список!B:B)=0)/(Список!F:F="А"),0),0)),"") -> Нестерова Екатерина Евгеньевна | E12: =IFERROR(INDEX(Список!G:G,MATCH(D12,Список!B:B,0)),"") -> 0
A13: 12 | B13: =IFERROR(INDEX(Список!A:A,MATCH(D13,Список!B:B,0)),"") -> ОГМетр | C13: 1 | D13: =IFERROR(INDEX(Список!B:B,MATCH(1,INDEX((COUNTIF(D$1:D12,Список!B:B)=0)/(Список!F:F="А"),0),0)),"") -> Канаев Сергей Александрович | E13: =IFERROR(INDEX(Список!G:G,MATCH(D13,Список!B:B,0)),"") -> 0
A14: 13 | B14: =IFERROR(INDEX(Список!A:A,MATCH(D14,Список!B:B,0)),"") -> ЦНИОКР | C14: 9 | D14: =IFERROR(INDEX(Список!B:B,MATCH(1,INDEX((COUNTIF(D$1:D13,Список!B:B)=0)/(Список!F:F="А"),0),0)),"") -> Типикина Мария Анатольевна | E14: =IFERROR(INDEX(Список!G:G,MATCH(D14,Список!B:B,0)),"") -> 0 | F14: =IFERROR(INDEX([1]Список!O:O,MATCH(Таблица243[[#This Row],[Капитаны]],[1]Список!D:D,0)),"")
A15: 14 | B15: =IFERROR(INDEX(Список!A:A,MATCH(D15,Список!B:B,0)),"") -> ЧОП | C15: 10 | D15: =IFERROR(INDEX(Список!B:B,MATCH(1,INDEX((COUNTIF(D$1:D14,Список!B:B)=0)/(Список!F:F="А"),0),0)),"") -> Рыжаков Степан Анатольевич | E15: =IFERROR(INDEX(Список!G:G,MATCH(D15,Список!B:B,0)),"") -> 0
A16: 15 | B16: =IFERROR(INDEX(Список!A:A,MATCH(D16,Список!B:B,0)),"") | D16: =IFERROR(INDEX(Список!B:B,MATCH(1,INDEX((COUNTIF(D$1:D15,Список!B:B)=0)/(Список!F:F="А"),0),0)),"") | E16: =IFERROR(INDEX(Список!G:G,MATCH(D16,Список!B:B,0)),"")
B17: =IFERROR(INDEX([1]Список!B:B,MATCH(Таблица243[[#This Row],[Капитаны]],[1]Список!D:D,0)),"")
B18: =IFERROR(INDEX([1]Список!B:B,MATCH(Таблица243[[#This Row],[Капитаны]],[1]Список!D:D,0)),"") | E18: =IFERROR(INDEX([1]Список!O:O,MATCH(Таблица243[[#This Row],[Капитаны]],[1]Список!D:D,0)),"")
B22: Здесь заполняем только столбец "жребий"
B24: При увеличении кол-во команд, необходимо увеличить поле таблицы (на всех страницах, кроме Список по соревнованиям)

Sheet Список
A1: Подразделение | B1: ФИО | C1: Пол | D1: туртехника | E1: ориентирование | F1: Капитаны | G1: Телефон | H1: Жеребьевка | I1: Дата
A2: СМП | B2: Макагон Иван Васильевич | C2: =IF(RIGHT(B2)="ч","М",IF(RIGHT(B2)="а","Ж",IF(RIGHT(B2)=".","---"," "))) -> М | D2: Т | H2: =IFERROR(INDEX(Таблица243[Жребий],MATCH(Список!A2,Таблица243[Подразделение],0)),"") -> 8 | I2: 32405
A3: СМП | B3: Развин Вячеслав Александрович | C3: =IF(RIGHT(B3)="ч","М",IF(RIGHT(B3)="а","Ж",IF(RIGHT(B3)=".","---"," "))) -> М | D3: Т | F3: А | G3: 11 | H3: =IFERROR(INDEX(Таблица243[Жребий],MATCH(Список!A3,Таблица243[Подразделение],0)),"") -> 8 | I3: 31807
A4: СМП | B4: Бояновская Анастасия Владимировна | C4: =IF(RIGHT(B4)="ч","М",IF(RIGHT(B4)="а","Ж",IF(RIGHT(B4)=".","---"," "))) -> Ж | H4: =IFERROR(INDEX(Таблица243[Жребий],MATCH(Список!A4,Таблица243[Подразделение],0)),"") -> 8 | I4: 32346
A5: СМП | B5: Госс Денис Александрович | C5: =IF(RIGHT(B5)="ч","М",IF(RIGHT(B5)="а","Ж",IF(RIGHT(B5)=".","---"," "))) -> М | D5: Т | H5: =IFERROR(INDEX(Таблица243[Жребий],MATCH(Список!A5,Таблица243[Подразделение],0)),"") -> 8 | I5: 30815
A6: СМП | B6: Валитов Равиль Наильевич | C6: =IF(RIGHT(B6)="ч","М",IF(RIGHT(B6)="а","Ж",IF(RIGHT(B6)=".","---"," "))) -> М | E6: С | H6: =IFERROR(INDEX(Таблица243[Жребий],MATCH(Список!A6,Таблица243[Подразделение],0)),"") -> 8 | I6: 34845
A7: СМП | B7: Жеребцов Андрей Викторович | C7: =IF(RIGHT(B7)="ч","М",IF(RIGHT(B7)="а","Ж",IF(RIGHT(B7)=".","---"," "))) -> М | E7: С | H7: =IFERROR(INDEX(Таблица243[Жребий],MATCH(Список!A7,Таблица243[Подразделение],0)),"") -> 8 | I7: 31758
A8: СМП | B8: Вася Петрович | C8: =IF(RIGHT(B8)="ч","М",IF(RIGHT(B8)="а","Ж",IF(RIGHT(B8)=".","---"," "))) -> М | E8: С | H8: =IFERROR(INDEX(Таблица243[Жребий],MATCH(Список!A8,Таблица243[Подразделение],0)),"") -> 8 | I8: 32313
A9: СМП | B9: Белодед Вероника Николаевна | C9: =IF(RIGHT(B9)="ч","М",IF(RIGHT(B9)="а","Ж",IF(RIGHT(B9)=".","---"," "))) -> Ж | D9: Т | H9: =IFERROR(INDEX(Таблица243[Жребий],MATCH(Список!A9,Таблица243[Подразделение],0)),"") -> 8 | I9: 26558
A10: СМП | B10: Дроздов Артём Викторович | C10: =IF(RIGHT(B10)="ч","М",IF(RIGHT(B10)="а","Ж",IF(RIGHT(B10)=".","---"," "))) -> М | H10: =IFERROR(INDEX(Таблица243[Жребий],MATCH(Список!A10,Таблица243[Подразделение],0)),"") -> 8 | I10: 30419
A11: СМП | B11: Савельева Екатерина Владимировна | C11: =IF(RIGHT(B11)="ч","М",IF(RIGHT(B11)="а","Ж",IF(RIGHT(B11)=".","---"," "))) -> Ж | H11: =IFERROR(INDEX(Таблица243[Жребий],MATCH(Список!A11,Таблица243[Подразделение],0)),"") -> 8 | I11: 32916
A12: СМП | B12: Маклаков Никита Сергеевич | C12: =IF(RIGHT(B12)="ч","М",IF(RIGHT(B12)="а","Ж",IF(RIGHT(B12)=".","---"," "))) -> М | H12: =IFERROR(INDEX(Таблица243[Жребий],MATCH(Список!A12,Таблица243[Подразделение],0)),"") -> 8 | I12: 34356
A13: СМП | B13: Трибушевский Олег Игоревич | C13: =IF(RIGHT(B13)="ч","М",IF(RIGHT(B13)="а","Ж",IF(RIGHT(B13)=".","---"," "))) -> М | H13: =IFERROR(INDEX(Таблица243[Жребий],MATCH(Список!A13,Таблица243[Подразделение],0)),"") -> 8 | I13: 30954
A14: СМП | B14: Черныш Владимир Юрьевич | C14: =IF(RIGHT(B14)="ч","М",IF(RIGHT(B14)="а","Ж",IF(RIGHT(B14)=".","---"," "))) -> М | H14: =IFERROR(INDEX(Таблица243[Жребий],MATCH(Список!A14,Таблица243[Подразделение],0)),"") -> 8 | I14: 31383
A15: СМП | B15: Прозорова Инна Наильевна | C15: =IF(RIGHT(B15)="ч","М",IF(RIGHT(B15)="а","Ж",IF(RIGHT(B15)=".","---"," "))) -> Ж | H15: =IFERROR(INDEX(Таблица243[Жребий],MATCH(Список!A15,Таблица243[Подразделение],0)),"") -> 8 | I15: 33033
A16: СМП | B16: Приходько Дмитрий Николаевич | C16: =IF(RIGHT(B16)="ч","М",IF(RIGHT(B16)="а","Ж",IF(RIGHT(B16)=".","---"," "))) -> М | E16: С | H16: =IFERROR(INDEX(Таблица243[Жребий],MATCH(Список!A16,Таблица243[Подразделение],0)),"") -> 8 | I16: 29965
A17: СМП | B17: Закревский Алексей Александрович | C17: =IF(RIGHT(B17)="ч","М",IF(RIGHT(B17)="а","Ж",IF(RIGHT(B17)=".","---"," "))) -> М | H17: =IFERROR(INDEX(Таблица243[Жребий],MATCH(Список!A17,Таблица243[Подразделение],0)),"") -> 8 | I17: 30477
A18: СМП | B18: Матвейчук Олег Петрович | C18: =IF(RIGHT(B18)="ч","М",IF(RIGHT(B18)="а","Ж",IF(RIGHT(B18)=".","---"," "))) -> М | H18: =IFERROR(INDEX(Таблица243[Жребий],MATCH(Список!A18,Таблица243[Подразделение],0)),"") -> 8 | I18: 25449
A19: МП | B19: Степико Денис Борисович | C19: =IF(RIGHT(B19)="ч","М",IF(RIGHT(B19)="а","Ж",IF(RIGHT(B19)=".","---"," "))) -> М | E19: С | H19: =IFERROR(INDEX(Таблица243[Жребий],MATCH(Список!A19,Таблица243[Подразделение],0)),"") -> 7 | I19: 32767
A20: МП | B20: Конышев Максим Михайлович | C20: =IF(RIGHT(B20)="ч","М",IF(RIGHT(B20)="а","Ж",IF(RIGHT(B20)=".","---"," "))) -> М | D20: Т | H20: =IFERROR(INDEX(Таблица243[Жребий],MATCH(Список!A20,Таблица243[Подразделение],0)),"") -> 7 | I20: 29199
A21: МП | B21: Штефи Владислав Петрович | C21: =IF(RIGHT(B21)="ч","М",IF(RIGHT(B21)="а","Ж",IF(RIGHT(B21)=".","---"," "))) -> М | D21: Т | E21: С | H21: =IFERROR(INDEX(Таблица243[Жребий],MATCH(Список!A21,Таблица243[Подразделение],0)),"") -> 7 | I21: 31742
A22: МП | B22: Журов Александр Александрович | C22: =IF(RIGHT(B22)="ч","М",IF(RIGHT(B22)="а","Ж",IF(RIGHT(B22)=".","---"," "))) -> М | D22: Т | H22: =IFERROR(INDEX(Таблица243[Жребий],MATCH(Список!A22,Таблица243[Подразделение],0)),"") -> 7 | I22: 32131
A23: МП | B23: Жаринова Ольга Юрьевна | C23: =IF(RIGHT(B23)="ч","М",IF(RIGHT(B23)="а","Ж",IF(RIGHT(B23)=".","---"," "))) -> Ж | D23: Т | H23: =IFERROR(INDEX(Таблица243[Жребий],MATCH(Список!A23,Таблица243[Подразделение],0)),"") -> 7 | I23: 29594
A24: МП | B24: Саматов Михаил Васильевич | C24: =IF(RIGHT(B24)="ч","М",IF(RIGHT(B24)="а","Ж",IF(RIGHT(B24)=".","---"," "))) -> М | E24: С | F24: А | G24: 22 | H24: =IFERROR(INDEX(Таблица243[Жребий],MATCH(Список!A24,Таблица243[Подразделение],0)),"") -> 7 | I24: 31084
A25: МП | B25: Михайлов Алексей Сергеевич | C25: =IF(RIGHT(B25)="ч","М",IF(RIGHT(B25)="а","Ж",IF(RIGHT(B25)=".","---"," "))) -> М | E25: С | H25: =IFERROR(INDEX(Таблица243[Жребий],MATCH(Список!A25,Таблица243[Подразделение],0)),"") -> 7 | I25: 34439
A26: МП | B26: Урусов Алексей Николаевич | C26: =IF(RIGHT(B26)="ч","М",IF(RIGHT(B26)="а","Ж",IF(RIGHT(B26)=".","---"," "))) -> М | H26: =IFERROR(INDEX(Таблица243[Жребий],MATCH(Список!A26,Таблица243[Подразделение],0)),"") -> 7 | I26: 30774
A27: МП | B27: Заливина Елена Александровна | C27: =IF(RIGHT(B27)="ч","М",IF(RIGHT(B27)="а","Ж",IF(RIGHT(B27)=".","---"," "))) -> Ж | H27: =IFERROR(INDEX(Таблица243[Жребий],MATCH(Список!A27,Таблица243[Подразделение],0)),"") -> 7 | I27: 25935
A28: МП | B28: Жаринов Леонид Алексеевич | C28: =IF(RIGHT(B28)="ч","М",IF(RIGHT(B28)="а","Ж",IF(RIGHT(B28)=".","---"," "))) -> М | H28: =IFERROR(INDEX(Таблица243[Жребий],MATCH(Список!A28,Таблица243[Подразделение],0)),"") -> 7 | I28: 28185
A29: МП | B29: Положенцев Евгений Владимирович | C29: =IF(RIGHT(B29)="ч","М",IF(RIGHT(B29)="а","Ж",IF(RIGHT(B29)=".","---"," "))) -> М | H29: =IFERROR(INDEX(Таблица243[Жребий],MATCH(Список!A29,Таблица243[Подразделение],0)),"") -> 7 | I29: 33245
A30: МП | B30: Колесников Дмитрий Александрович | C30: =IF(RIGHT(B30)="ч","М",IF(RIGHT(B30)="а","Ж",IF(RIGHT(B30)=".","---"," "))) -> М | H30: =IFERROR(INDEX(Таблица243[Жребий],MATCH(Список!A30,Таблица243[Подразделение],0)),"") -> 7 | I30: 28074
A31: МП | B31: Коновалов Юрий Анатольевич | C31: =IF(RIGHT(B31)="ч","М",IF(RIGHT(B31)="а","Ж",IF(RIGHT(B31)=".","---"," "))) -> М | H31: =IFERROR(INDEX(Таблица243[Жребий],MATCH(Список!A31,Таблица243[Подразделение],0)),"") -> 7 | I31: 32778
A32: МП | B32: Панков Владимир Евгеньевич | C32: =IF(RIGHT(B32)="ч","М",IF(RIGHT(B32)="а","Ж",IF(RIGHT(B32)=".","---"," "))) -> М | H32: =IFERROR(INDEX(Таблица243[Жребий],MATCH(Список!A32,Таблица243[Подразделение],0)),"") -> 7 | I32: 32403
A33: МП | B33: Лапшин Алексей Валерьевич | C33: =IF(RIGHT(B33)="ч","М",IF(RIGHT(B33)="а","Ж",IF(RIGHT(B33)=".","---"," "))) -> М | H33: =IFERROR(INDEX(Таблица243[Жребий],MATCH(Список!A33,Таблица243[Подразделение],0)),"") -> 7 | I33: 29552
A34: МП | B34: Жильцов Александр Александрович | C34: =IF(RIGHT(B34)="ч","М",IF(RIGHT(B34)="а","Ж",IF(RIGHT(B34)=".","---"," "))) -> М | H34: =IFERROR(INDEX(Таблица243[Жребий],MATCH(Список!A34,Таблица243[Подразделение],0)),"") -> 7 | I34: 30543
A35: ц.35 | B35: Белозёров Иван Викторович | C35: =IF(RIGHT(B35)="ч","М",IF(RIGHT(B35)="а","Ж",IF(RIGHT(B35)=".","---"," "))) -> М | D35: Т | H35: =IFERROR(INDEX(Таблица243[Жребий],MATCH(Список!A35,Таблица243[Подразделение],0)),"") -> 14 | I35: 15.17.1987
A36: ц.35 | B36: Железкин Александр Сергеевич | C36: =IF(RIGHT(B36)="ч","М",IF(RIGHT(B36)="а","Ж",IF(RIGHT(B36)=".","---"," "))) -> М | D36: Т | H36: =IFERROR(INDEX(Таблица243[Жребий],MATCH(Список!A36,Таблица243[Подразделение],0)),"") -> 14 | I36: 32610
A37: ц.35 | B37: Кустов Сергей Анатольевич | C37: =IF(RIGHT(B37)="ч","М",IF(RIGHT(B37)="а","Ж",IF(RIGHT(B37)=".","---"," "))) -> М | D37: Т | H37: =IFERROR(INDEX(Таблица243[Жребий],MATCH(Список!A37,Таблица243[Подразделение],0)),"") -> 14 | I37: 30601
A38: ц.35 | B38: Беляева Ангелина Генриховна | C38: =IF(RIGHT(B38)="ч","М",IF(RIGHT(B38)="а","Ж",IF(RIGHT(B38)=".","---"," "))) -> Ж | D38: Т | H38: =IFERROR(INDEX(Таблица243[Жребий],MATCH(Список!A38,Таблица243[Подразделение],0)),"") -> 14 | I38: 33555
A39: ц.35 | B39: Филипчик Алексей Иванович | C39: =IF(RIGHT(B39)="ч","М",IF(RIGHT(B39)="а","Ж",IF(RIGHT(B39)=".","---"," "))) -> М | E39: С | H39: =IFERROR(INDEX(Таблица243[Жребий],MATCH(Список!A39,Таблица243[Подразделение],0)),"") -> 14 | I39: 29007
A40: ц.35 | B40: Дубляженко Павел Евгеньевич | C40: =IF(RIGHT(B40)="ч","М",IF(RIGHT(B40)="а","Ж",IF(RIGHT(B40)=".","---"," "))) -> М | E40: С | H40: =IFERROR(INDEX(Таблица243[Жребий],MATCH(Список!A40,Таблица243[Подразделение],0)),"") -> 14 | I40: 33137
...

Sheet Список ориентирование 
A1: № п/п | B1: Подразд. | C1: Ф.И.О. | D1: Группа | E1: № | G1: Подразд. | H1: Ф.И.О. | I1: Группа | J1: №
A2: 1 | B2: СМП | C2: Валитов Равиль Наильевич | D2: М | E2: 1 | G2: ц.35 | H2: Ивахно Любовь Сергеевна | I2: Ж | J2: 1
A3: 5 | B3: МП | C3: Степико Денис Борисович | D3: М | E3: 2 | G3: ц.38 | H3: Поликарпова Анастасия Вячеславовна | I3: Ж | J3: 2
A4: 9 | B4: ц.35 | C4: Филипчик Алексей Иванович | D4: М | E4: 3 | G4: СГМ | H4: Михайлюк Анна Леонидовна | I4: Ж | J4: 3
A5: 12 | B5: ц.38 | C5: Серёгин ЕвгенийЕвгеньевич | D5: М | E5: 4 | G5: АХС | H5: Першаева Мария Александровна | I5: Ж | J5: 4
A6: 15 | B6: СГМ | C6: Прикуль Виталий Владимирович | D6: М | E6: 5 | G6: ОТД+ОГК | H6: Дорощенко Елена Ивановна | I6: Ж | J6: 5
A7: 17 | B7: ц.63 | C7: Дахов Артур Сергеевич | D7: М | E7: 6 | G7: ОГТ | H7: Пашкова Александра Сергеевна | I7: Ж | J7: 6
A8: 21 | B8: ц.65 | C8: Дьяконов Дмитрий Васильевич | D8: М | E8: 7 | G8: СУКП | H8: Наумова Елена Сергеевна | I8: Ж | J8: 7
A9: 25 | B9: АХС | C9: Шлома Алексей Владимирович | D9: М | E9: 8 | G9: СГМ | H9: Варлакова Ирина Сергеевна | I9: Ж | J9: 8
A10: 26 | B10: ОТД+ОГК | C10: Толбин Игорь Анатольевич | D10: М | E10: 9 | G10: АХС | H10: Дай Ольга Николаевна | I10: Ж | J10: 9
A11: 29 | B11: ОГТ | C11: Сухарев Дмитрий Андреевич | D11: М | E11: 10 | G11: ОГТ | H11: Анфёрова Ирина Александровна | I11: Ж | J11: 10
A12: 30 | B12: СУКП | C12: Иванов Алексей Васильевич | D12: М | E12: 11 | G12: АХС | H12: Киселёва Инна Васильевна | I12: Ж | J12: 11
A13: 2 | B13: СМП | C13: Жеребцов Андрей Викторович | D13: М | E13: 12 | G13: ОГТ | H13: Зорянова Александра Валерьевна | I13: Ж | J13: 12
... A16: 13 | B16: ц.38 | C16: Комаров Илья Андреевич | D16: М | E16: 15 | G16: ЦНИОКР | H16: Абрамова Елена Геннадьевна | I16: Ж | J16: 15
A17: 16 | B17: СГМ | C17: Грушецкий Вячеслав Валерьевич | D17: М | E17: 16
A18: 18 | B18: ц.63 | C18: Ионин Евгений Валерьевич | D18: М | E18: 17
A19: 22 | B19: ц.65 | C19: Волосанов Дмитрий Александрович | D19: М | E19: 18
A20: 27 | B20: ОТД+ОГК | C20: Молчанов Сергей Алексеевич | D20: М | E20: 19
A21: 31 | B21: СУКП | C21: Гречишников Дмитрий Сергеевич | D21: М | E21: 20
A22: 3 | B22: СМП | C22: Вася Петрович | D22: М | E22: 21
A23: 7 | B23: МП | C23: Саматов Михаил Васильевич | D23: М | E23: 22
A24: 11 | B24: ц.35 | C24: Бабкин Илья Андреевич | D24: М | E24: 23
A25: 14 | B25: ц.38 | C25: Федосеев Сергей Николаевич | D25: М | E25: 24
A26: 19 | B26: ц.63 | C26: Сабранский Вячеслав Владимирович | D26: М | E26: 25
A27: 23 | B27: ц.65 | C27: Шахматов Вячеслав Владимирович | D27: М | E27: 26
A28: 28 | B28: ОТД+ОГК | C28: Тырон Александр Евгеньевич | D28: М | E28: 27
... A39: 38 | B39: ЧОП | C39: ШайдулинРамисИльдарович | D39: М | E39: 38

Sheet Ориентирование-сводная
A1: Стартовый протокол Ориентирование (командный зачет)
A2: Жребий | B2: Подразд. | C2: Ф.И.О. | D2: Пол | E2: № участника | F2: Пол | G2: Итоговое время | H2: Время команды | I2: Место | J2: Баллы | L2: № | M2: Подразд. | N2: ВРЕМЯ | O2: МЕСТО | P2: Баллы
A3: 1 | B3: СМП | C3: Валитов Равиль Наильевич | D3: М | E3: 1 | F3: М | G3: =IF(D3="М",IFERROR(INDEX('Старт М'!$I$3:$I$101,MATCH('Ориентирование-сводная'!C3,'Старт М'!$C$3:$C$101,0)),""),IFERROR(INDEX('Старт Ж'!$I$3:$I$101,MATCH('Ориентирование-сводная'!C3,'Старт Ж'!$C$3:$C$101,0)),"")) -> 0.11563657 | H3: =SUM(G3:G6) -> 0.50868056 | I3: =INDEX($O$3:$O$34,MATCH($H$3:$H$82,$N$3:$N$34,0)) -> XIII | J3: =INDEX($P$3:$P$34,MATCH($H$3:$H$171,$N$3:$N$34,0)) -> 8 | L3: 1 | M3: =INDEX($B$3:$B$82,MATCH(N3,$H$2:$H$82,0)) -> ЦНИОКР | N3: =SMALL($H$3:$H$71,1) -> 0.18805556 | O3: I | P3: 30
A4: 1 | B4: СМП | C4: Жеребцов Андрей Викторович | D4: М | E4: 2 | F4: Ж | G4: =IF(D4="М",IFERROR(INDEX('Старт М'!$I$3:$I$101,MATCH('Ориентирование-сводная'!C4,'Старт М'!$C$3:$C$101,0)),""),IFERROR(INDEX('Старт Ж'!$I$3:$I$101,MATCH('Ориентирование-сводная'!C4,'Старт Ж'!$C$3:$C$101,0)),"")) -> 0.1484375 | L4: 2 | M4: =INDEX($B$3:$B$82,MATCH(N4,$H$2:$H$82,0)) -> ц.35 | N4: =SMALL($H$3:$H$71,2) -> 0.23368056 | O4: II | P4: 28
A5: 1 | B5: СМП | C5: Вася Петрович | D5: М | E5: 3 | F5: М | G5: =IF(D5="М",IFERROR(INDEX('Старт М'!$I$3:$I$101,MATCH('Ориентирование-сводная'!C5,'Старт М'!$C$3:$C$101,0)),""),IFERROR(INDEX('Старт Ж'!$I$3:$I$101,MATCH('Ориентирование-сводная'!C5,'Старт Ж'!$C$3:$C$101,0)),"")) -> 0.1421875 | L5: 3 | M5: =INDEX($B$3:$B$82,MATCH(N5,$H$2:$H$82,0)) -> ЧОП | N5: =SMALL($H$3:$H$71,3) -> 0.24719907 | O5: III | P5: 26
A6: 1 | B6: СМП | C6: Приходько Дмитрий Николаевич | D6: М | E6: 4 | F6: М | G6: =IF(D6="М",IFERROR(INDEX('Старт М'!$I$3:$I$101,MATCH('Ориентирование-сводная'!C6,'Старт М'!$C$3:$C$101,0)),""),IFERROR(INDEX('Старт Ж'!$I$3:$I$101,MATCH('Ориентирование-сводная'!C6,'Старт Ж'!$C$3:$C$101,0)),"")) -> 0.10241898 | L6: 4 | M6: =INDEX($B$3:$B$82,MATCH(N6,$H$2:$H$82,0)) -> ОГМетр | N6: =SMALL($H$3:$H$71,4) -> 0.25960648 | O6: IV | P6: 24
A7: 2 | B7: МП | C7: Степико Денис Борисович | D7: М | E7: 5 | F7: Ж | G7: =IF(D7="М",IFERROR(INDEX('Старт М'!$I$3:$I$101,MATCH('Ориентирование-сводная'!C7,'Старт М'!$C$3:$C$101,0)),""),IFERROR(INDEX('Старт Ж'!$I$3:$I$101,MATCH('Ориентирование-сводная'!C7,'Старт Ж'!$C$3:$C$101,0)),"")) -> 0.072581019 | H7: =SUM(G7:G10) -> 0.51446759 | I7: =INDEX($O$3:$O$34,MATCH($H$3:$H$82,$N$3:$N$34,0)) -> XIV | J7: =INDEX($P$3:$P$34,MATCH($H$3:$H$171,$N$3:$N$34,0)) -> 7 | L7: 5 | M7: =INDEX($B$3:$B$82,MATCH(N7,$H$2:$H$82,0)) -> СУКП | N7: =SMALL($H$3:$H$71,5) -> 0.27266204 | O7: V | P7: 22
A8: 2 | B8: МП | C8: Штефи Владислав Петрович | D8: М | E8: 6 | F8: М | G8: =IF(D8="М",IFERROR(INDEX('Старт М'!$I$3:$I$101,MATCH('Ориентирование-сводная'!C8,'Старт М'!$C$3:$C$101,0)),""),IFERROR(INDEX('Старт Ж'!$I$3:$I$101,MATCH('Ориентирование-сводная'!C8,'Старт Ж'!$C$3:$C$101,0)),"")) -> 0.20916667 | L8: 6 | M8: =INDEX($B$3:$B$82,MATCH(N8,$H$2:$H$82,0)) -> ОТД+ОГК | N8: =SMALL($H$3:$H$71,6) -> 0.2777662 | O8: VI | P8: 20
A9: 2 | B9: МП | C9: Саматов Михаил Васильевич | D9: М | E9: 7 | F9: М | G9: =IF(D9="М",IFERROR(INDEX('Старт М'!$I$3:$I$101,MATCH('Ориентирование-сводная'!C9,'Старт М'!$C$3:$C$101,0)),""),IFERROR(INDEX('Старт Ж'!$I$3:$I$101,MATCH('Ориентирование-сводная'!C9,'Старт Ж'!$C$3:$C$101,0)),"")) -> 0.11888889 | L9: 7 | M9: =INDEX($B$3:$B$82,MATCH(N9,$H$2:$H$82,0)) -> ОГТ | N9: =SMALL($H$3:$H$71,7) -> 0.305 | O9: VII | P9: 18
A10: 2 | B10: МП | C10: Михайлов Алексей Сергеевич | D10: М | E10: 8 | F10: М | G10: =IF(D10="М",IFERROR(INDEX('Старт М'!$I$3:$I$101,MATCH('Ориентирование-сводная'!C10,'Старт М'!$C$3:$C$101,0)),""),IFERROR(INDEX('Старт Ж'!$I$3:$I$101,MATCH('Ориентирование-сводная'!C10,'Старт Ж'!$C$3:$C$101,0)),"")) -> 0.11383102 | L10: 8 | M10: =INDEX($B$3:$B$82,MATCH(N10,$H$2:$H$82,0)) -> ц.63 | N10: =SMALL($H$3:$H$71,8) -> 0.32469907 | O10: VIII | P10: 16
A11: 3 | B11: ц.35 | C11: Филипчик Алексей Иванович | D11: М | E11: 9 | F11: М | G11: =IF(D11="М",IFERROR(INDEX('Старт М'!$I$3:$I$101,MATCH('Ориентирование-сводная'!C11,'Старт М'!$C$3:$C$101,0)),""),IFERROR(INDEX('Старт Ж'!$I$3:$I$101,MATCH('Ориентирование-сводная'!C11,'Старт Ж'!$C$3:$C$101,0)),"")) -> 0.11355324 | H11: =SUM(G11:G14) -> 0.23368056 | I11: =INDEX($O$3:$O$34,MATCH($H$3:$H$82,$N$3:$N$34,0)) -> II | J11: =INDEX($P$3:$P$34,MATCH($H$3:$H$171,$N$3:$N$34,0)) -> 28 | L11: 9 | M11: =INDEX($B$3:$B$82,MATCH(N11,$H$2:$H$82,0)) -> ц.65 | N11: =SMALL($H$3:$H$71,9) -> 0.33304398 | O11: IX | P11: 14
A12: 3 | B12: ц.35 | C12: Дубляженко Павел Евгеньевич | D12: М | E12: 10 | F12: М | G12: =IF(D12="М",IFERROR(INDEX('Старт М'!$I$3:$I$101,MATCH('Ориентирование-сводная'!C12,'Старт М'!$C$3:$C$101,0)),""),IFERROR(INDEX('Старт Ж'!$I$3:$I$101,MATCH('Ориентирование-сводная'!C12,'Старт Ж'!$C$3:$C$101,0)),"")) -> 0.047384259 | L12: 10 | M12: =INDEX($B$3:$B$82,MATCH(N12,$H$2:$H$82,0)) -> АХС | N12: =SMALL($H$3:$H$71,10) -> 0.34353009 | O12: X | P12: 12
A13: 3 | B13: ц.35 | C13: Бабкин Илья Андреевич | D13: М | E13: 11 | F13: М | G13: =IF(D13="М",IFERROR(INDEX('Старт М'!$I$3:$I$101,MATCH('Ориентирование-сводная'!C13,'Старт М'!$C$3:$C$101,0)),""),IFERROR(INDEX('Старт Ж'!$I$3:$I$101,MATCH('Ориентирование-сводная'!C13,'Старт Ж'!$C$3:$C$101,0)),"")) -> 0.041134259 | L13: 11 | M13: =INDEX($B$3:$B$82,MATCH(N13,$H$2:$H$82,0)) -> ц.38 | N13: =SMALL($H$3:$H$71,11) -> 0.36224537 | O13: XI | P13: 10
A14: 3 | B14: ц.35 | C14: Ивахно Любовь Сергеевна | D14: Ж | E14: 12 | F14: Ж | G14: =IF(D14="М",IFERROR(INDEX('Старт М'!$I$3:$I$101,MATCH('Ориентирование-сводная'!C14,'Старт М'!$C$3:$C$101,0)),""),IFERROR(INDEX('Старт Ж'!$I$3:$I$101,MATCH('Ориентирование-сводная'!C14,'Старт Ж'!$C$3:$C$101,0)),"")) -> 0.031608796 | L14: 12 | M14: =INDEX($B$3:$B$82,MATCH(N14,$H$2:$H$82,0)) -> СГМ | N14: =SMALL($H$3:$H$71,12) -> 0.4733912 | O14: XII | P14: 9
A15: 4 | B15: ц.38 | C15: Серёгин ЕвгенийЕвгеньевич | D15: М | E15: 13 | F15: Ж | G15: =IF(D15="М",IFERROR(INDEX('Старт М'!$I$3:$I$101,MATCH('Ориентирование-сводная'!C15,'Старт М'!$C$3:$C$101,0)),""),IFERROR(INDEX('Старт Ж'!$I$3:$I$101,MATCH('Ориентирование-сводная'!C15,'Старт Ж'!$C$3:$C$101,0)),"")) -> 0.15452546 | H15: =SUM(G15:G18) -> 0.36224537 | I15: =INDEX($O$3:$O$34,MATCH($H$3:$H$82,$N$3:$N$34,0)) -> XI | J15: =INDEX($P$3:$P$34,MATCH($H$3:$H$171,$N$3:$N$34,0)) -> 10 | L15: 13 | M15: =INDEX($B$3:$B$82,MATCH(N15,$H$2:$H$82,0)) -> СМП | N15: =SMALL($H$3:$H$71,13) -> 0.50868056 | O15: XIII | P15: 8
A16: 4 | B16: ц.38 | C16: Комаров Илья Андреевич | D16: М | E16: 14 | F16: М | G16: =IF(D16="М",IFERROR(INDEX('Старт М'!$I$3:$I$101,MATCH('Ориентирование-сводная'!C16,'Старт М'!$C$3:$C$101,0)),""),IFERROR(INDEX('Старт Ж'!$I$3:$I$101,MATCH('Ориентирование-сводная'!C16,'Старт Ж'!$C$3:$C$101,0)),"")) -> 0.055729167 | L16: 14 | M16: =INDEX($B$3:$B$82,MATCH(N16,$H$2:$H$82,0)) -> МП | N16: =SMALL($H$3:$H$71,14) -> 0.51446759 | O16: XIV | P16: 7
A17: 4 | B17: ц.38 | C17: Федосеев Сергей Николаевич | D17: М | E17: 15 | F17: М | G17: =IF(D17="М",IFERROR(INDEX('Старт М'!$I$3:$I$101,MATCH('Ориентирование-сводная'!C17,'Старт М'!$C$3:$C$101,0)),""),IFERROR(INDEX('Старт Ж'!$I$3:$I$101,MATCH('Ориентирование-сводная'!C17,'Старт Ж'!$C$3:$C$101,0)),"")) -> 0.049479167 | O17: XV | P17: 6
A18: 4 | B18: ц.38 | C18: Поликарпова Анастасия Вячеславовна | D18: Ж | E18: 16 | F18: М | G18: =IF(D18="М",IFERROR(INDEX('Старт М'!$I$3:$I$101,MATCH('Ориентирование-сводная'!C18,'Старт М'!$C$3:$C$101,0)),""),IFERROR(INDEX('Старт Ж'!$I$3:$I$101,MATCH('Ориентирование-сводная'!C18,'Старт Ж'!$C$3:$C$101,0)),"")) -> 0.10251157 | O18: XVI | P18: 5
A19: 5 | B19: СГМ | C19: Михайлюк Анна Леонидовна | D19: Ж | E19: 17 | F19: М | G19: =IF(D19="М",IFERROR(INDEX('Старт М'!$I$3:$I$101,MATCH('Ориентирование-сводная'!C19,'Старт М'!$C$3:$C$101,0)),""),IFERROR(INDEX('Старт Ж'!$I$3:$I$101,MATCH('Ориентирование-сводная'!C19,'Старт Ж'!$C$3:$C$101,0)),"")) -> 0.10181713 | H19: =SUM(G19:G22) -> 0.4733912 | I19: =INDEX($O$3:$O$34,MATCH($H$3:$H$82,$N$3:$N$34,0)) -> XII | J19: =INDEX($P$3:$P$34,MATCH($H$3:$H$171,$N$3:$N$34,0)) -> 9 | O19: XVII | P19: 4
A20: 5 | B20: СГМ | C20: Варлакова Ирина Сергеевна | D20: Ж | E20: 18 | F20: Ж | G20: =IF(D20="М",IFERROR(INDEX('Старт М'!$I$3:$I$101,MATCH('Ориентирование-сводная'!C20,'Старт М'!$C$3:$C$101,0)),""),IFERROR(INDEX('Старт Ж'!$I$3:$I$101,MATCH('Ориентирование-сводная'!C20,'Старт Ж'!$C$3:$C$101,0)),"")) -> 0.08068287 | O20: XVIII | P20: 3
A21: 5 | B21: СГМ | C21: Прикуль Виталий Владимирович | D21: М | E21: 19 | F21: М | G21: =IF(D21="М",IFERROR(INDEX('Старт М'!$I$3:$I$101,MATCH('Ориентирование-сводная'!C21,'Старт М'!$C$3:$C$101,0)),""),IFERROR(INDEX('Старт Ж'!$I$3:$I$101,MATCH('Ориентирование-сводная'!C21,'Старт Ж'!$C$3:$C$101,0)),"")) -> 0.22787037 | O21: XIX | P21: 2
A22: 5 | B22: СГМ | C22: Грушецкий Вячеслав Валерьевич | D22: М | E22: 20 | F22: Ж | G22: =IF(D22="М",IFERROR(INDEX('Старт М'!$I$3:$I$101,MATCH('Ориентирование-сводная'!C22,'Старт М'!$C$3:$C$101,0)),""),IFERROR(INDEX('Старт Ж'!$I$3:$I$101,MATCH('Ориентирование-сводная'!C22,'Старт Ж'!$C$3:$C$101,0)),"")) -> 0.063020833 | O22: XX | P22: 1
A23: 6 | B23: ц.63 | C23: Дахов Артур Сергеевич | D23: М | E23: 21 | F23: Ж | G23: =IF(D23="М",IFERROR(INDEX('Старт М'!$I$3:$I$101,MATCH('Ориентирование-сводная'!C23,'Старт М'!$C$3:$C$101,0)),""),IFERROR(INDEX('Старт Ж'!$I$3:$I$101,MATCH('Ориентирование-сводная'!C23,'Старт Ж'!$C$3:$C$101,0)),"")) -> 0.068252315 | H23: =SUM(G23:G26) -> 0.32469907 | I23: =INDEX($O$3:$O$34,MATCH($H$3:$H$82,$N$3:$N$34,0)) -> VIII | J23: =INDEX($P$3:$P$34,MATCH($H$3:$H$171,$N$3:$N$34,0)) -> 16
A24: 6 | B24: ц.63 | C24: Ионин Евгений Валерьевич | D24: М | E24: 22 | F24: Ж | G24: =IF(D24="М",IFERROR(INDEX('Старт М'!$I$3:$I$101,MATCH('Ориентирование-сводная'!C24,'Старт М'!$C$3:$C$101,0)),""),IFERROR(INDEX('Старт Ж'!$I$3:$I$101,MATCH('Ориентирование-сводная'!C24,'Старт Ж'!$C$3:$C$101,0)),"")) -> 0.07443287
A25: 6 | B25: ц.63 | C25: Сабранский Вячеслав Владимирович | D25: М | E25: 23 | F25: Ж | G25: =IF(D25="М",IFERROR(INDEX('Старт М'!$I$3:$I$101,MATCH('Ориентирование-сводная'!C25,'Старт М'!$C$3:$C$101,0)),""),IFERROR(INDEX('Старт Ж'!$I$3:$I$101,MATCH('Ориентирование-сводная'!C25,'Старт Ж'!$C$3:$C$101,0)),"")) -> 0.056770833
A26: 6 | B26: ц.63 | C26: Погребняк Андрей Григорьевич | D26: М | E26: 24 | F26: М | G26: =IF(D26="М",IFERROR(INDEX('Старт М'!$I$3:$I$101,MATCH('Ориентирование-сводная'!C26,'Старт М'!$C$3:$C$101,0)),""),IFERROR(INDEX('Старт Ж'!$I$3:$I$101,MATCH('Ориентирование-сводная'!C26,'Старт Ж'!$C$3:$C$101,0)),"")) -> 0.12524306
A27: 7 | B27: ц.65 | C27: Дьяконов Дмитрий Васильевич | D27: М | E27: 25 | F27: М | G27: =IF(D27="М",IFERROR(INDEX('Старт М'!$I$3:$I$101,MATCH('Ориентирование-сводная'!C27,'Старт М'!$C$3:$C$101,0)),""),IFERROR(INDEX('Старт Ж'!$I$3:$I$101,MATCH('Ориентирование-сводная'!C27,'Старт Ж'!$C$3:$C$101,0)),"")) -> 0.069270833 | H27: =SUM(G27:G30) -> 0.33304398 | I27: =INDEX($O$3:$O$34,MATCH($H$3:$H$82,$N$3:$N$34,0)) -> IX | J27: =INDEX($P$3:$P$34,MATCH($H$3:$H$171,$N$3:$N$34,0)) -> 14
A28: 7 | B28: ц.65 | C28: Волосанов Дмитрий Александрович | D28: М | E28: 26 | F28: М | G28: =IF(D28="М",IFERROR(INDEX('Старт М'!$I$3:$I$101,MATCH('Ориентирование-сводная'!C28,'Старт М'!$C$3:$C$101,0)),""),IFERROR(INDEX('Старт Ж'!$I$3:$I$101,MATCH('Ориентирование-сводная'!C28,'Старт Ж'!$C$3:$C$101,0)),"")) -> 0.058935185
A29: 7 | B29: ц.65 | C29: Шахматов Вячеслав Владимирович | D29: М | E29: 27 | F29: М | G29: =IF(D29="М",IFERROR(INDEX('Старт М'!$I$3:$I$101,MATCH('Ориентирование-сводная'!C29,'Старт М'!$C$3:$C$101,0)),""),IFERROR(INDEX('Старт Ж'!$I$3:$I$101,MATCH('Ориентирование-сводная'!C29,'Старт Ж'!$C$3:$C$101,0)),"")) -> 0.06818287
A30: 7 | B30: ц.65 | C30: Недоступ Евгений Николаевич | D30: М | E30: 28 | F30: Ж | G30: =IF(D30="М",IFERROR(INDEX('Старт М'!$I$3:$I$101,MATCH('Ориентирование-сводная'!C30,'Старт М'!$C$3:$C$101,0)),""),IFERROR(INDEX('Старт Ж'!$I$3:$I$101,MATCH('Ориентирование-сводная'!C30,'Старт Ж'!$C$3:$C$101,0)),"")) -> 0.13665509
A31: 8 | B31: АХС | C31: Шлома Алексей Владимирович | D31: М | E31: 29 | F31: М | G31: =IF(D31="М",IFERROR(INDEX('Старт М'!$I$3:$I$101,MATCH('Ориентирование-сводная'!C31,'Старт М'!$C$3:$C$101,0)),""),IFERROR(INDEX('Старт Ж'!$I$3:$I$101,MATCH('Ориентирование-сводная'!C31,'Старт Ж'!$C$3:$C$101,0)),"")) -> 0.08068287 | H31: =SUM(G31:G34) -> 0.34353009 | I31: =INDEX($O$3:$O$34,MATCH($H$3:$H$82,$N$3:$N$34,0)) -> X | J31: =INDEX($P$3:$P$34,MATCH($H$3:$H$171,$N$3:$N$34,0)) -> 12
A32: 8 | B32: АХС | C32: Першаева Мария Александровна | D32: Ж | E32: 30 | F32: М | G32: =IF(D32="М",IFERROR(INDEX('Старт М'!$I$3:$I$101,MATCH('Ориентирование-сводная'!C32,'Старт М'!$C$3:$C$101,0)),""),IFERROR(INDEX('Старт Ж'!$I$3:$I$101,MATCH('Ориентирование-сводная'!C32,'Старт Ж'!$C$3:$C$101,0)),"")) -> 0.13116898
A33: 8 | B33: АХС | C33: Дай Ольга Николаевна | D33: Ж | E33: 31 | F33: Ж | G33: =IF(D33="М",IFERROR(INDEX('Старт М'!$I$3:$I$101,MATCH('Ориентирование-сводная'!C33,'Старт М'!$C$3:$C$101,0)),""),IFERROR(INDEX('Старт Ж'!$I$3:$I$101,MATCH('Ориентирование-сводная'!C33,'Старт Ж'!$C$3:$C$101,0)),"")) -> 0.065185185
A34: 8 | B34: АХС | C34: Киселёва Инна Васильевна | D34: Ж | E34: 32 | F34: М | G34: =IF(D34="М",IFERROR(INDEX('Старт М'!$I$3:$I$101,MATCH('Ориентирование-сводная'!C34,'Старт М'!$C$3:$C$101,0)),""),IFERROR(INDEX('Старт Ж'!$I$3:$I$101,MATCH('Ориентирование-сводная'!C34,'Старт Ж'!$C$3:$C$101,0)),"")) -> 0.066493056
A35: 9 | B35: ОТД+ОГК | C35: Толбин Игорь Анатольевич | D35: М | E35: 33 | G35: =IF(D35="М",IFERROR(INDEX('Старт М'!$I$3:$I$101,MATCH('Ориентирование-сводная'!C35,'Старт М'!$C$3:$C$101,0)),""),IFERROR(INDEX('Старт Ж'!$I$3:$I$101,MATCH('Ориентирование-сводная'!C35,'Старт Ж'!$C$3:$C$101,0)),"")) -> 0.065185185 | H35: =SUM(G35:G38) -> 0.2777662 | I35: =INDEX($O$3:$O$34,MATCH($H$3:$H$82,$N$3:$N$34,0)) -> VI | J35: =INDEX($P$3:$P$34,MATCH($H$3:$H$171,$N$3:$N$34,0)) -> 20
A36: 9 | B36: ОТД+ОГК | C36: Молчанов Сергей Алексеевич | D36: М | E36: 34 | G36: =IF(D36="М",IFERROR(INDEX('Старт М'!$I$3:$I$101,MATCH('Ориентирование-сводная'!C36,'Старт М'!$C$3:$C$101,0)),""),IFERROR(INDEX('Старт Ж'!$I$3:$I$101,MATCH('Ориентирование-сводная'!C36,'Старт Ж'!$C$3:$C$101,0)),"")) -> 0.073171296
A37: 9 | B37: ОТД+ОГК | C37: Тырон Александр Евгеньевич | D37: М | E37: 35 | G37: =IF(D37="М",IFERROR(INDEX('Старт М'!$I$3:$I$101,MATCH('Ориентирование-сводная'!C37,'Старт М'!$C$3:$C$101,0)),""),IFERROR(INDEX('Старт Ж'!$I$3:$I$101,MATCH('Ориентирование-сводная'!C37,'Старт Ж'!$C$3:$C$101,0)),"")) -> 0.079594907
A38: 9 | B38: ОТД+ОГК | C38: Дорощенко Елена Ивановна | D38: Ж | E38: 36 | G38: =IF(D38="М",IFERROR(INDEX('Старт М'!$I$3:$I$101,MATCH('Ориентирование-сводная'!C38,'Старт М'!$C$3:$C$101,0)),""),IFERROR(INDEX('Старт Ж'!$I$3:$I$101,MATCH('Ориентирование-сводная'!C38,'Старт Ж'!$C$3:$C$101,0)),"")) -> 0.059814815
A39: 10 | B39: ОГТ | C39: Сухарев Дмитрий Андреевич | D39: М | E39: 37 | G39: =IF(D39="М",IFERROR(INDEX('Старт М'!$I$3:$I$101,MATCH('Ориентирование-сводная'!C39,'Старт М'!$C$3:$C$101,0)),""),IFERROR(INDEX('Старт Ж'!$I$3:$I$101,MATCH('Ориентирование-сводная'!C39,'Старт Ж'!$C$3:$C$101,0)),"")) -> 0.079421296 | H39: =SUM(G39:G42) -> 0.305 | I39: =INDEX($O$3:$O$34,MATCH($H$3:$H$82,$N$3:$N$34,0)) -> VII | J39: =INDEX($P$3:$P$34,MATCH($H$3:$H$171,$N$3:$N$34,0)) -> 18
A40: 10 | B40: ОГТ | C40: Пашкова Александра Сергеевна | D40: Ж | E40: 38 | G40: =IF(D40="М",IFERROR(INDEX('Старт М'!$I$3:$I$101,MATCH('Ориентирование-сводная'!C40,'Старт М'!$C$3:$C$101,0)),""),IFERROR(INDEX('Старт Ж'!$I$3:$I$101,MATCH('Ориентирование-сводная'!C40,'Старт Ж'!$C$3:$C$101,0)),"")) -> 0.068252315
...

Sheet Старт Ж
C1: Стартовый протокол Ориентирование. Группа М
B2: Подразд. | C2: Ф.И.О. | D2: Номер | E2: Время старта | F2: Время финиша | G2: Итоговое время | H2: Не найдено КП | I2: Время с учетом штрафов | K2: Подразд. | L2: Ф.И.О. | M2: ВРЕМЯ | N2: МЕСТО | P2: Предупреждение о том, что не нашел КП
A3: 1 | B3: ц.35 | C3: Ивахно Любовь Сергеевна | D3: 1 | E3: 0.00069444444 | F3: 0.032303241 | G3: =IF(ISBLANK(F3),"",F3-E3) -> 0.031608796 | I3: =IF(ISBLANK(F3),"",G3+TIME(H3*2,H3,0)) -> 0.031608796 | K3: =INDEX(B:B,MATCH(M3,I:I,0)) -> ц.35 | L3: =INDEX(C:C,MATCH(M3,I:I,0)) -> Ивахно Любовь Сергеевна | M3: =IFERROR(SMALL(I3:I200,1)," ") -> 0.031608796 | N3: I
A4: 2 | B4: ц.38 | C4: Поликарпова Анастасия Вячеславовна | D4: 2 | E4: 0.0013888889 | F4: 0.10390046 | G4: =IF(ISBLANK(F4),"",F4-E4) -> 0.10251157 | I4: =IF(ISBLANK(F4),"",G4+TIME(H4*2,H4,0)) -> 0.10251157 | K4: =INDEX(B:B,MATCH(M4,I:I,0)) -> ОТД+ОГК | L4: =INDEX(C:C,MATCH(M4,I:I,0)) -> Дорощенко Елена Ивановна | M4: =IFERROR(SMALL(I3:I200,2)," ") -> 0.059814815 | N4: II
A5: 3 | B5: СГМ | C5: Михайлюк Анна Леонидовна | D5: 3 | E5: 0.0020833333 | F5: 0.10390046 | G5: =IF(ISBLANK(F5),"",F5-E5) -> 0.10181713 | I5: =IF(ISBLANK(F5),"",G5+TIME(H5*2,H5,0)) -> 0.10181713 | K5: =INDEX(B:B,MATCH(M5,I:I,0)) -> ЦНИОКР | L5: =INDEX(C:C,MATCH(M5,I:I,0)) -> Абрамова Елена Геннадьевна | M5: =IFERROR(SMALL(I3:I200,3)," ") -> 0.061018519 | N5: III
A6: 4 | B6: АХС | C6: Першаева Мария Александровна | D6: 4 | E6: 0.0027777778 | F6: 0.049918981 | G6: =IF(ISBLANK(F6),"",F6-E6) -> 0.047141204 | H6: 1 | I6: =IF(ISBLANK(F6),"",G6+TIME(H6*2,H6,0)) -> 0.13116898 | K6: =INDEX(B:B,MATCH(M6,I:I,0)) -> ОГМетр | L6: =INDEX(C:C,MATCH(M6,I:I,0)) -> Евдокименко Елена Владимировна | M6: =IFERROR(SMALL(I3:I200,4)," ") -> 0.065104167 | N6: IV
A7: 5 | B7: ОТД+ОГК | C7: Дорощенко Елена Ивановна | D7: 5 | E7: 0.0034722222 | F7: 0.063287037 | G7: =IF(ISBLANK(F7),"",F7-E7) -> 0.059814815 | I7: =IF(ISBLANK(F7),"",G7+TIME(H7*2,H7,0)) -> 0.059814815 | K7: =INDEX(B:B,MATCH(M7,I:I,0)) -> АХС | L7: =INDEX(C:C,MATCH(M7,I:I,0)) -> Дай Ольга Николаевна | M7: =IFERROR(SMALL(I3:I200,5)," ") -> 0.065185185 | N7: V
A8: 6 | B8: ОГТ | C8: Пашкова Александра Сергеевна | D8: 6 | E8: 0.0041666667 | F8: 0.072418981 | G8: =IF(ISBLANK(F8),"",F8-E8) -> 0.068252315 | I8: =IF(ISBLANK(F8),"",G8+TIME(H8*2,H8,0)) -> 0.068252315
A9: 7 | B9: СУКП | C9: Наумова Елена Сергеевна | D9: 7 | E9: 0.0048611111 | F9: 0.074131944 | G9: =IF(ISBLANK(F9),"",F9-E9) -> 0.069270833 | I9: =IF(ISBLANK(F9),"",G9+TIME(H9*2,H9,0)) -> 0.069270833
A10: 8 | B10: СГМ | C10: Варлакова Ирина Сергеевна | D10: 8 | E10: 0.0055555556 | F10: 0.086238426 | G10: =IF(ISBLANK(F10),"",F10-E10) -> 0.08068287 | I10: =IF(ISBLANK(F10),"",G10+TIME(H10*2,H10,0)) -> 0.08068287
A11: 9 | B11: АХС | C11: Дай Ольга Николаевна | D11: 9 | E11: 0.00625 | F11: 0.071435185 | G11: =IF(ISBLANK(F11),"",F11-E11) -> 0.065185185 | I11: =IF(ISBLANK(F11),"",G11+TIME(H11*2,H11,0)) -> 0.065185185
A12: 10 | B12: ОГТ | C12: Анфёрова Ирина Александровна | D12: 10 | E12: 0.0069444444 | F12: 0.086365741 | G12: =IF(ISBLANK(F12),"",F12-E12) -> 0.079421296 | I12: =IF(ISBLANK(F12),"",G12+TIME(H12*2,H12,0)) -> 0.079421296
A13: 11 | B13: АХС | C13: Киселёва Инна Васильевна | D13: 11 | E13: 0.0076388889 | F13: 0.074131944 | G13: =IF(ISBLANK(F13),"",F13-E13) -> 0.066493056 | I13: =IF(ISBLANK(F13),"",G13+TIME(H13*2,H13,0)) -> 0.066493056
A14: 12 | B14: ОГТ | C14: Зорянова Александра Валерьевна | D14: 12 | E14: 0.0083333333 | F14: 0.086238426 | G14: =IF(ISBLANK(F14),"",F14-E14) -> 0.077905093 | I14: =IF(ISBLANK(F14),"",G14+TIME(H14*2,H14,0)) -> 0.077905093
A15: 13 | B15: ОГМетр | C15: Евдокименко Елена Владимировна | D15: 13 | E15: 0.0090277778 | F15: 0.074131944 | G15: =IF(ISBLANK(F15),"",F15-E15) -> 0.065104167 | I15: =IF(ISBLANK(F15),"",G15+TIME(H15*2,H15,0)) -> 0.065104167
A16: 14 | B16: ЦНИОКР | C16: Шевчук Анастасия Алексеевна | D16: 14 | E16: 0.0097222222 | F16: 0.086238426 | G16: =IF(ISBLANK(F16),"",F16-E16) -> 0.076516204 | I16: =IF(ISBLANK(F16),"",G16+TIME(H16*2,H16,0)) -> 0.076516204
A17: 15 | B17: ЦНИОКР | C17: Абрамова Елена Геннадьевна | D17: 15 | E17: 0.010416667 | F17: 0.071435185 | G17: =IF(ISBLANK(F17),"",F17-E17) -> 0.061018519 | I17: =IF(ISBLANK(F17),"",G17+TIME(H17*2,H17,0)) -> 0.061018519
A18: 16 | G18: =IF(ISBLANK(F18),"",F18-E18) | I18: =IF(ISBLANK(F18),"",G18+TIME(H18*2,H18,0))
A19: 17 | G19: =IF(ISBLANK(F19),"",F19-E19) | I19: =IF(ISBLANK(F19),"",G19+TIME(H19*2,H19,0))
A20: 18 | G20: =IF(ISBLANK(F20),"",F20-E20) | I20: =IF(ISBLANK(F20),"",G20+TIME(H20*2,H20,0))
A21: 19 | G21: =IF(ISBLANK(F21),"",F21-E21) | I21: =IF(ISBLANK(F21),"",G21+TIME(H21*2,H21,0))
A22: 20 | B22: =IFERROR(INDEX('Список ориентирование '!G:G,MATCH(A22,'Список ориентирование '!J:J,0)),"") | C22: =IFERROR(INDEX('Список ориентирование '!H:H,MATCH(A22,'Список ориентирование '!J:J,0)),"") | G22: =IF(ISBLANK(F22),"",F22-E22) | I22: =IF(ISBLANK(F22),"",G22+TIME(H22*2,H22,0))
A23: 21 | B23: =IFERROR(INDEX('Список ориентирование '!G:G,MATCH(A23,'Список ориентирование '!J:J,0)),"") | C23: =IFERROR(INDEX('Список ориентирование '!H:H,MATCH(A23,'Список ориентирование '!J:J,0)),"") | G23: =IF(ISBLANK(F23),"",F23-E23) | I23: =IF(ISBLANK(F23),"",G23+TIME(H23*2,H23,0))
A24: 22 | B24: =IFERROR(INDEX('Список ориентирование '!G:G,MATCH(A24,'Список ориентирование '!J:J,0)),"") | C24: =IFERROR(INDEX('Список ориентирование '!H:H,MATCH(A24,'Список ориентирование '!J:J,0)),"") | G24: =IF(ISBLANK(F24),"",F24-E24) | I24: =IF(ISBLANK(F24),"",G24+TIME(H24*2,H24,0))
A25: 23 | B25: =IFERROR(INDEX('Список ориентирование '!G:G,MATCH(A25,'Список ориентирование '!J:J,0)),"") | C25: =IFERROR(INDEX('Список ориентирование '!H:H,MATCH(A25,'Список ориентирование '!J:J,0)),"") | G25: =IF(ISBLANK(F25),"",F25-E25) | I25: =IF(ISBLANK(F25),"",G25+TIME(H25*2,H25,0))
A26: 24 | B26: =IFERROR(INDEX('Список ориентирование '!G:G,MATCH(A26,'Список ориентирование '!J:J,0)),"") | C26: =IFERROR(INDEX('Список ориентирование '!H:H,MATCH(A26,'Список ориентирование '!J:J,0)),"") | G26: =IF(ISBLANK(F26),"",F26-E26) | I26: =IF(ISBLANK(F26),"",G26+TIME(H26*2,H26,0))
A27: 25 | B27: =IFERROR(INDEX('Список ориентирование '!G:G,MATCH(A27,'Список ориентирование '!J:J,0)),"") | C27: =IFERROR(INDEX('Список ориентирование '!H:H,MATCH(A27,'Список ориентирование '!J:J,0)),"") | G27: =IF(ISBLANK(F27),"",F27-E27) | I27: =IF(ISBLANK(F27),"",G27+TIME(H27*2,H27,0))
A28: 26 | B28: =IFERROR(INDEX('Список ориентирование '!G:G,MATCH(A28,'Список ориентирование '!J:J,0)),"") | C28: =IFERROR(INDEX('Список ориентирование '!H:H,MATCH(A28,'Список ориентирование '!J:J,0)),"") | G28: =IF(ISBLANK(F28),"",F28-E28) | I28: =IF(ISBLANK(F28),"",G28+TIME(H28*2,H28,0))
A29: 27 | B29: =IFERROR(INDEX('Список ориентирование '!G:G,MATCH(A29,'Список ориентирование '!J:J,0)),"") | C29: =IFERROR(INDEX('Список ориентирование '!H:H,MATCH(A29,'Список ориентирование '!J:J,0)),"") | G29: =IF(ISBLANK(F29),"",F29-E29) | I29: =IF(ISBLANK(F29),"",G29+TIME(H29*2,H29,0))
A30: 28 | B30: =IFERROR(INDEX('Список ориентирование '!G:G,MATCH(A30,'Список ориентирование '!J:J,0)),"") | C30: =IFERROR(INDEX('Список ориентирование '!H:H,MATCH(A30,'Список ориентирование '!J:J,0)),"") | G30: =IF(ISBLANK(F30),"",F30-E30) | I30: =IF(ISBLANK(F30),"",G30+TIME(H30*2,H30,0))
A31: 29 | B31: =IFERROR(INDEX('Список ориентирование '!G:G,MATCH(A31,'Список ориентирование '!J:J,0)),"") | C31: =IFERROR(INDEX('Список ориентирование '!H:H,MATCH(A31,'Список ориентирование '!J:J,0)),"") | G31: =IF(ISBLANK(F31),"",F31-E31) | I31: =IF(ISBLANK(F31),"",G31+TIME(H31*2,H31,0))
A32: 30 | B32: =IFERROR(INDEX('Список ориентирование '!G:G,MATCH(A32,'Список ориентирование '!J:J,0)),"") | C32: =IFERROR(INDEX('Список ориентирование '!H:H,MATCH(A32,'Список ориентирование '!J:J,0)),"") | G32: =IF(ISBLANK(F32),"",F32-E32) | I32: =IF(ISBLANK(F32),"",G32+TIME(H32*2,H32,0))
A33: 31 | B33: =IFERROR(INDEX('Список ориентирование '!G:G,MATCH(A33,'Список ориентирование '!J:J,0)),"") | C33: =IFERROR(INDEX('Список ориентирование '!H:H,MATCH(A33,'Список ориентирование '!J:J,0)),"") | G33: =IF(ISBLANK(F33),"",F33-E33) | I33: =IF(ISBLANK(F33),"",G33+TIME(H33*2,H33,0))
... A101: 99 | B101: =IFERROR(INDEX('Список ориентирование '!G:G,MATCH(A101,'Список ориентирование '!J:J,0)),"") | C101: =IFERROR(INDEX('Список ориентирование '!H:H,MATCH(A101,'Список ориентирование '!J:J,0)),"") | G101: =IF(ISBLANK(F101),"",F101-E101) | I101: =IF(ISBLANK(F101),"",G101+TIME(H101*2,H101,0))

Sheet Старт М
C1: Стартовый протокол Ориентирование. Группа М
B2: Подразд. | C2: Ф.И.О. | D2: Номер | E2: Время старта | F2: Время финиша | G2: Итоговое время | H2: Не найдено КП | I2: Время с учетом штрафов | K2: Подразд. | L2: Ф.И.О. | M2: ВРЕМЯ | N2: МЕСТО | P2: Предупреждение о том, что не нашел КП
A3: 1 | B3: СМП | C3: Валитов Равиль Наильевич | E3: 0.00069444444 | F3: 0.032303241 | G3: =IF(ISBLANK(F3),"",F3-E3) -> 0.031608796 | H3: 1 | I3: =IF(ISBLANK(F3),"",G3+TIME(H3*2,H3,0)) -> 0.11563657 | K3: =INDEX(B:B,MATCH(M3,I:I,0)) -> ц.35 | L3: =INDEX(C:C,MATCH(M3,I:I,0)) -> Бабкин Илья Андреевич | M3: =IFERROR(SMALL(I3:I200,1)," ") -> 0.041134259 | N3: I
A4: 2 | B4: МП | C4: Степико Денис Борисович | E4: 0.0013888889 | F4: 0.073969907 | G4: =IF(ISBLANK(F4),"",F4-E4) -> 0.072581019 | I4: =IF(ISBLANK(F4),"",G4+TIME(H4*2,H4,0)) -> 0.072581019 | K4: =INDEX(B:B,MATCH(M4,I:I,0)) -> ОГМетр | L4: =INDEX(C:C,MATCH(M4,I:I,0)) -> Маринкин Алексей Владимирович | M4: =IFERROR(SMALL(I3:I200,2)," ") -> 0.046435185 | N4: II
A5: 3 | B5: ц.35 | C5: Филипчик Алексей Иванович | E5: 0.0020833333 | F5: 0.11563657 | G5: =IF(ISBLANK(F5),"",F5-E5) -> 0.11355324 | I5: =IF(ISBLANK(F5),"",G5+TIME(H5*2,H5,0)) -> 0.11355324 | K5: =INDEX(B:B,MATCH(M5,I:I,0)) -> ц.35 | L5: =INDEX(C:C,MATCH(M5,I:I,0)) -> Дубляженко Павел Евгеньевич | M5: =IFERROR(SMALL(I3:I200,3)," ") -> 0.047384259 | N5: III
A6: 4 | B6: ц.38 | C6: Серёгин ЕвгенийЕвгеньевич | E6: 0.0027777778 | F6: 0.15730324 | G6: =IF(ISBLANK(F6),"",F6-E6) -> 0.15452546 | I6: =IF(ISBLANK(F6),"",G6+TIME(H6*2,H6,0)) -> 0.15452546 | K6: =INDEX(B:B,MATCH(M6,I:I,0)) -> ц.38 | L6: =INDEX(C:C,MATCH(M6,I:I,0)) -> Федосеев Сергей Николаевич | M6: =IFERROR(SMALL(I3:I200,4)," ") -> 0.049479167 | N6: IV
A7: 5 | B7: СГМ | C7: Прикуль Виталий Владимирович | E7: 0.0034722222 | F7: 0.063287037 | G7: =IF(ISBLANK(F7),"",F7-E7) -> 0.059814815 | H7: 2 | I7: =IF(ISBLANK(F7),"",G7+TIME(H7*2,H7,0)) -> 0.22787037 | K7: =INDEX(B:B,MATCH(M7,I:I,0)) -> ЦНИОКР | L7: =INDEX(C:C,MATCH(M7,I:I,0)) -> Шабанов Дмитрий Николаевич | M7: =IFERROR(SMALL(I3:I200,5)," ") -> 0.050520833 | N7: V
A8: 6 | B8: ц.63 | C8: Дахов Артур Сергеевич | E8: 0.0041666667 | F8: 0.072418981 | G8: =IF(ISBLANK(F8),"",F8-E8) -> 0.068252315 | I8: =IF(ISBLANK(F8),"",G8+TIME(H8*2,H8,0)) -> 0.068252315
A9: 7 | B9: ц.65 | C9: Дьяконов Дмитрий Васильевич | E9: 0.0048611111 | F9: 0.074131944 | G9: =IF(ISBLANK(F9),"",F9-E9) -> 0.069270833 | I9: =IF(ISBLANK(F9),"",G9+TIME(H9*2,H9,0)) -> 0.069270833
A10: 8 | B10: АХС | C10: Шлома Алексей Владимирович | E10: 0.0055555556 | F10: 0.086238426 | G10: =IF(ISBLANK(F10),"",F10-E10) -> 0.08068287 | I10: =IF(ISBLANK(F10),"",G10+TIME(H10*2,H10,0)) -> 0.08068287
A11: 9 | B11: ОТД+ОГК | C11: Толбин Игорь Анатольевич | E11: 0.00625 | F11: 0.071435185 | G11: =IF(ISBLANK(F11),"",F11-E11) -> 0.065185185 | I11: =IF(ISBLANK(F11),"",G11+TIME(H11*2,H11,0)) -> 0.065185185
A12: 10 | B12: ОГТ | C12: Сухарев Дмитрий Андреевич | E12: 0.0069444444 | F12: 0.086365741 | G12: =IF(ISBLANK(F12),"",F12-E12) -> 0.079421296 | I12: =IF(ISBLANK(F12),"",G12+TIME(H12*2,H12,0)) -> 0.079421296
A13: 11 | B13: СУКП | C13: Иванов Алексей Васильевич | E13: 0.0076388889 | F13: 0.066956019 | G13: =IF(ISBLANK(F13),"",F13-E13) -> 0.05931713 | I13: =IF(ISBLANK(F13),"",G13+TIME(H13*2,H13,0)) -> 0.05931713
A14: 12 | B14: СМП | C14: Жеребцов Андрей Викторович | E14: 0.0083333333 | F14: 0.15677083 | G14: =IF(ISBLANK(F14),"",F14-E14) -> 0.1484375 | I14: =IF(ISBLANK(F14),"",G14+TIME(H14*2,H14,0)) -> 0.1484375
A15: 13 | B15: МП | C15: Штефи Владислав Петрович | E15: 0.0090277778 | F15: 0.050138889 | G15: =IF(ISBLANK(F15),"",F15-E15) -> 0.041111111 | H15: 2 | I15: =IF(ISBLANK(F15),"",G15+TIME(H15*2,H15,0)) -> 0.20916667
A16: 14 | B16: ц.35 | C16: Дубляженко Павел Евгеньевич | E16: 0.0097222222 | F16: 0.057106481 | G16: =IF(ISBLANK(F16),"",F16-E16) -> 0.047384259 | I16: =IF(ISBLANK(F16),"",G16+TIME(H16*2,H16,0)) -> 0.047384259
A17: 15 | B17: ц.38 | C17: Комаров Илья Андреевич | E17: 0.010416667 | F17: 0.066145833 | G17: =IF(ISBLANK(F17),"",F17-E17) -> 0.055729167 | I17: =IF(ISBLANK(F17),"",G17+TIME(H17*2,H17,0)) -> 0.055729167
A18: 16 | B18: СГМ | C18: Грушецкий Вячеслав Валерьевич | E18: 0.011111111 | F18: 0.074131944 | G18: =IF(ISBLANK(F18),"",F18-E18) -> 0.063020833 | I18: =IF(ISBLANK(F18),"",G18+TIME(H18*2,H18,0)) -> 0.063020833
A19: 17 | B19: ц.63 | C19: Ионин Евгений Валерьевич | E19: 0.011805556 | F19: 0.086238426 | G19: =IF(ISBLANK(F19),"",F19-E19) -> 0.07443287 | I19: =IF(ISBLANK(F19),"",G19+TIME(H19*2,H19,0)) -> 0.07443287
A20: 18 | B20: ц.65 | C20: Волосанов Дмитрий Александрович | E20: 0.0125 | F20: 0.071435185 | G20: =IF(ISBLANK(F20),"",F20-E20) -> 0.058935185 | I20: =IF(ISBLANK(F20),"",G20+TIME(H20*2,H20,0)) -> 0.058935185
A21: 19 | B21: ОТД+ОГК | C21: Молчанов Сергей Алексеевич | E21: 0.013194444 | F21: 0.086365741 | G21: =IF(ISBLANK(F21),"",F21-E21) -> 0.073171296 | I21: =IF(ISBLANK(F21),"",G21+TIME(H21*2,H21,0)) -> 0.073171296
A22: 20 | B22: СУКП | C22: Гречишников Дмитрий Сергеевич | E22: 0.013888889 | F22: 0.066956019 | G22: =IF(ISBLANK(F22),"",F22-E22) -> 0.05306713 | I22: =IF(ISBLANK(F22),"",G22+TIME(H22*2,H22,0)) -> 0.05306713
A23: 21 | B23: СМП | C23: Вася Петрович | E23: 0.014583333 | F23: 0.15677083 | G23: =IF(ISBLANK(F23),"",F23-E23) -> 0.1421875 | I23: =IF(ISBLANK(F23),"",G23+TIME(H23*2,H23,0)) -> 0.1421875
A24: 22 | B24: МП | C24: Саматов Михаил Васильевич | E24: 0.015277778 | F24: 0.050138889 | G24: =IF(ISBLANK(F24),"",F24-E24) -> 0.034861111 | H24: 1 | I24: =IF(ISBLANK(F24),"",G24+TIME(H24*2,H24,0)) -> 0.11888889
A25: 23 | B25: ц.35 | C25: Бабкин Илья Андреевич | E25: 0.015972222 | F25: 0.057106481 | G25: =IF(ISBLANK(F25),"",F25-E25) -> 0.041134259 | I25: =IF(ISBLANK(F25),"",G25+TIME(H25*2,H25,0)) -> 0.041134259
A26: 24 | B26: ц.38 | C26: Федосеев Сергей Николаевич | E26: 0.016666667 | F26: 0.066145833 | G26: =IF(ISBLANK(F26),"",F26-E26) -> 0.049479167 | I26: =IF(ISBLANK(F26),"",G26+TIME(H26*2,H26,0)) -> 0.049479167
A27: 25 | B27: ц.63 | C27: Сабранский Вячеслав Владимирович | E27: 0.017361111 | F27: 0.074131944 | G27: =IF(ISBLANK(F27),"",F27-E27) -> 0.056770833 | I27: =IF(ISBLANK(F27),"",G27+TIME(H27*2,H27,0)) -> 0.056770833
A28: 26 | B28: ц.65 | C28: Шахматов Вячеслав Владимирович | E28: 0.018055556 | F28: 0.086238426 | G28: =IF(ISBLANK(F28),"",F28-E28) -> 0.06818287 | I28: =IF(ISBLANK(F28),"",G28+TIME(H28*2,H28,0)) -> 0.06818287
A29: 27 | B29: ОТД+ОГК | C29: Тырон Александр Евгеньевич | E29: 0.01875 | F29: 0.098344907 | G29: =IF(ISBLANK(F29),"",F29-E29) -> 0.079594907 | I29: =IF(ISBLANK(F29),"",G29+TIME(H29*2,H29,0)) -> 0.079594907
A30: 28 | B30: СУКП | C30: Павлюченко Вячеслав Иванович | E30: 0.019444444 | F30: 0.11045139 | G30: =IF(ISBLANK(F30),"",F30-E30) -> 0.091006944 | I30: =IF(ISBLANK(F30),"",G30+TIME(H30*2,H30,0)) -> 0.091006944
A31: 29 | B31: СМП | C31: Приходько Дмитрий Николаевич | E31: 0.020138889 | F31: 0.12255787 | G31: =IF(ISBLANK(F31),"",F31-E31) -> 0.10241898 | I31: =IF(ISBLANK(F31),"",G31+TIME(H31*2,H31,0)) -> 0.10241898
A32: 30 | B32: МП | C32: Михайлов Алексей Сергеевич | E32: 0.020833333 | F32: 0.13466435 | G32: =IF(ISBLANK(F32),"",F32-E32) -> 0.11383102 | I32: =IF(ISBLANK(F32),"",G32+TIME(H32*2,H32,0)) -> 0.11383102
A33: 31 | B33: ц.63 | C33: Погребняк Андрей Григорьевич | E33: 0.021527778 | F33: 0.14677083 | G33: =IF(ISBLANK(F33),"",F33-E33) -> 0.12524306 | I33: =IF(ISBLANK(F33),"",G33+TIME(H33*2,H33,0)) -> 0.12524306
A34: 32 | B34: ц.65 | C34: Недоступ Евгений Николаевич | E34: 0.022222222 | F34: 0.15887731 | G34: =IF(ISBLANK(F34),"",F34-E34) -> 0.13665509 | I34: =IF(ISBLANK(F34),"",G34+TIME(H34*2,H34,0)) -> 0.13665509
A35: 33 | B35: ОГМетр | C35: Ковригин Евгений Павлович | E35: 0.022916667 | F35: 0.1709838 | G35: =IF(ISBLANK(F35),"",F35-E35) -> 0.14806713 | I35: =IF(ISBLANK(F35),"",G35+TIME(H35*2,H35,0)) -> 0.14806713
A36: 34 | B36: ЦНИОКР | C36: Шабанов Дмитрий Николаевич | E36: 0.023611111 | F36: 0.074131944 | G36: =IF(ISBLANK(F36),"",F36-E36) -> 0.050520833 | I36: =IF(ISBLANK(F36),"",G36+TIME(H36*2,H36,0)) -> 0.050520833
... A39: 37 | B39: ЧОП | C39: Вяткин Фёдор Александрович | E39: 0.025694444 | F39: 0.086365741 | G39: =IF(ISBLANK(F39),"",F39-E39) -> 0.060671296 | I39: =IF(ISBLANK(F39),"",G39+TIME(H39*2,H39,0)) -> 0.060671296
A40: 38 | B40: ЧОП | C40: ШайдулинРамисИльдарович | E40: 0.026388889 | F40: 0.066956019 | G40: =IF(ISBLANK(F40),"",F40-E40) -> 0.04056713 | H40: 1 | I40: =IF(ISBLANK(F40),"",G40+TIME(H40*2,H40,0)) -> 0.12459491
A41: 39 | G41: =IF(ISBLANK(F41),"",F41-E41) | I41: =IF(ISBLANK(F41),"",G41+TIME(H41*2,H41,0))
A42: 40 | G42: =IF(ISBLANK(F42),"",F42-E42) | I42: =IF(ISBLANK(F42),"",G42+TIME(H42*2,H42,0))
...
